Workbook

Sheet JAN-26
A1: Service ID | B1: Customer Name | C1: Mobile Number | D1: Watch Brand | E1: Model | F1: Problem Reported | G1: Received Date | H1: Expected Delivery Date | I1: Service Charge (₹) | J1: Advance Paid (₹) | K1: Balance Amount (₹) | L1: Service Status | M1: Delivered Date | N1: Remarks | O1: Notify | P1: WhatsApp Link | Q1: Customer WhatsappLink | S1: =IFERROR(__xludf.DUMMYFUNCTION("SUM(ARRAYFORMULA( REGEXMATCH(LOWER(L2:L506),""pending|in progress"")* (H2:H506<TODAY())*1 )) "),11.0) -> 11
A2: 2483 | B2: MR.MUTHIYAN | C2: 9952302155 | D2: TITAN RAGA | E2: 2543(SM\L) | F2: MG | G2: 46023 | H2: 46026 | I2: 100 | L2: Delivered | M2: 46030 | O2: YES | P2: =IF(O2="YES", "https://wa.me/?text=" & ENCODEURL( IF(OR(L2="Pending",L2="In Progress"), "⚠ *SERVICE ALERT – ATTENTION REQUIRED*" & CHAR(10) & CHAR(10), "📢 *SERVICE STATUS UPDATE*" & CHAR(10) & CHAR(10) ) & "Service ID: " & A2 & CHAR(10) & "Customer: " & B2 & CHAR(10) & "Mobile: " & C2 & CHAR(10) & "Brand: " & D2 & CHAR(10) & "Problem: " & F2 & CHAR(10) & CHAR(10) & "Received Date: " & TEXT(G2,"dd-mmm-yyyy") & CHAR(10) & "Expected Delivery Date: " & TEXT(H2,"dd-mmm-yyyy") & CHAR(10) & "Current Status: *" & L2 & "*" & CHAR(10) & CHAR(10) & IF(OR(L2="Pending",L2="In Progress"), "⚠ Please follow up immediately.", "✅ Service update for information." ) & CHAR(10) & CHAR(10) & "Balance Amount: ₹" & K2 & CHAR(10) & CHAR(10) & "— SMART TIMES SERVICE" ), "") -> https://wa.me/?text=%F0%9F%93%A2%20%2ASERVICE%20STATUS%20UPDATE%2A%0A%0AService%20ID%3A%202483%0ACustomer%3A%20MR.MUTHIYAN%0AMobile%3A%209952302155%0ABrand%3A%20TITAN%20RAGA%0AProblem%3A%20MG%0A%0AReceived%20Date%3A%2001-Jan-2026%0AExpected%20Delivery%20Date%3A%2004-Jan-2026%0ACurrent%20Status%3A%20%2ADelivered%2A%0A%0A%E2%9C%85%20Service%20update%20for%20information.%0A%0ABalance%20Amount%3A%20%E2%82%B9%0A%0A%E2%80%94%20SMART%20TIMES%20SERVICE | Q2: =IFERROR(__xludf.DUMMYFUNCTION("IF(REGEXMATCH(LOWER(L2),""ready""), ""https://wa.me/91""&C2&""?text="" & ENCODEURL( ""📢 *SERVICE READY – READY FOR COLLECTION*"" & CHAR(10) & CHAR(10) & ""📌 *English*"" & CHAR(10) & ""Dear "" & B2 & "","" & CHAR(10) & ""Your watch service is completed"&" and ready for collection."" & CHAR(10) & ""Brand: "" & D2 & CHAR(10) & ""Problem: "" & F2 & CHAR(10) & ""Received Date: "" & TEXT(G2,""dd-mmm-yyyy"") & CHAR(10) & ""Ready Date: "" & TEXT(H2,""dd-mmm-yyyy"") & CHAR(10) & ""Balance Amount: ₹"" & K2 & CHAR("&"10) & CHAR(10) & ""📍 *Shop Address:*"" & CHAR(10) & ""SMART TIMES,"" & CHAR(10) & ""8/107, Pennagaram Main Road,"" & CHAR(10) & ""Next to R.C Church,"" & CHAR(10) & ""Dharmapuri – 636701"" & CHAR(10) & CHAR(10) & ""🗺 *Google Map:* https://maps.app.goo."&"gl/DpPkfna7HQttxYXn9"" & CHAR(10) & CHAR(10) & ""📌 *தமிழ்*"" & CHAR(10) & ""வணக்கம் "" & B2 & "","" & CHAR(10) & ""உங்கள் கடிகார சர்வீஸ் முடிந்து, பெற்றுக்கொள்ள தயாராக உள்ளது."" & CHAR(10) & ""தயவுசெய்து கடைக்கு வந்து பெற்றுக்கொள்ளவும்."" & CHAR(10) & "&"""பிராண்ட்: "" & D2 & CHAR(10) & ""பெறப்பட்ட தேதி: "" & TEXT(G2,""dd-mmm-yyyy"") & CHAR(10) & ""தயார் தேதி: "" & TEXT(H2,""dd-mmm-yyyy"") & CHAR(10) & ""மீதத் தொகை: ₹"" & K2 & CHAR(10) & CHAR(10) & ""🗺 *Google Map:* https://maps.app.goo.gl/DpPkfna7HQttx"&"YXn9"" & CHAR(10) & CHAR(10) & ""🙏 SMART TIMES SERVICE"" ), """") "),"") | R2: =HYPERLINK(Q2,"🟢 SEND WHATSAPP") -> 🟢 SEND WHATSAPP | S2: =IFERROR(__xludf.DUMMYFUNCTION("TEXTJOIN(CHAR(10),TRUE, FILTER( A2:A506 & "" | Rec: "" & TEXT(G2:G506,""dd-mmm"") & "" | Exp: "" & TEXT(H2:H506,""dd-mmm""), (REGEXMATCH(LOWER(L2:L506),""pending|in progress""))* (H2:H506<TODAY()) ) ) "),"2492 | Rec: 04-Jan | Exp: 14-Jan 2492 | Rec: 04-Jan | Exp: 14-Jan 2496 | Rec: 05-Jan | Exp: 09-Jan 2497 | Rec: 05-Jan | Exp: 09-Jan 2504 | Rec: 08-Jan | Exp: 11-Jan 2505 | Rec: 09-Jan | Exp: 13-Jan 2505 | Rec: 09-Jan | Exp: 13-Jan 2507 | Rec: 11-Jan | Exp"&": 21-Jan 2508 | Rec: 11-Jan | Exp: 14-Jan 2509 | Rec: 12-Jan | Exp: 14-Jan 2510 | Rec: 12-Jan | Exp: 14-Jan") -> 2492 | Rec: 04-Jan | Exp: 14-Jan 2492 | Rec: 04-Jan | Exp: 14-Jan 2496 | Rec: 05-Jan | Exp: 09-Jan 2497 | Rec: 05-Jan | Exp: 09-Jan 2504 | Rec: 08-Jan | Exp: 11-Jan 2505 | Rec: 09-Jan | Exp: 13-Jan 2505 | Rec: 09-Jan | Exp: 13-Jan 2507 | Rec: 11-Jan | Exp: 21-Jan 2508 | Rec: 11-Jan | Exp: 14-Jan 2509 | Rec: 12-Jan | Exp: 14-Jan 2510 | Rec: 12-Jan | Exp: 14-Jan
A3: =A2+1 -> 2484 | B3: MRS.SHANTHI | C3: 8015336933 | D3: TITAN | E3: 2594(YM\G) | F3: SERVICE | G3: 46023 | H3: 46026 | I3: 350 | J3: 0 | K3: =I3-J3 -> 350 | L3: Ready | O3: YES | P3: =IF(O3="YES", "https://wa.me/?text=" & ENCODEURL( IF(OR(L3="Pending",L3="In Progress"), "⚠ *SERVICE ALERT – ATTENTION REQUIRED*" & CHAR(10) & CHAR(10), "📢 *SERVICE STATUS UPDATE*" & CHAR(10) & CHAR(10) ) & "Service ID: " & A3 & CHAR(10) & "Customer: " & B3 & CHAR(10) & "Mobile: " & C3 & CHAR(10) & "Brand: " & D3 & CHAR(10) & "Problem: " & F3 & CHAR(10) & CHAR(10) & "Received Date: " & TEXT(G3,"dd-mmm-yyyy") & CHAR(10) & "Expected Delivery Date: " & TEXT(H3,"dd-mmm-yyyy") & CHAR(10) & "Current Status: *" & L3 & "*" & CHAR(10) & CHAR(10) & IF(OR(L3="Pending",L3="In Progress"), "⚠ Please follow up immediately.", "✅ Service update for information." ) & CHAR(10) & CHAR(10) & "Balance Amount: ₹" & K3 & CHAR(10) & CHAR(10) & "— SMART TIMES SERVICE" ), "") -> https://wa.me/?text=%F0%9F%93%A2%20%2ASERVICE%20STATUS%20UPDATE%2A%0A%0AService%20ID%3A%202484%0ACustomer%3A%20MRS.SHANTHI%0AMobile%3A%208015336933%0ABrand%3A%20TITAN%0AProblem%3A%20SERVICE%0A%0AReceived%20Date%3A%2001-Jan-2026%0AExpected%20Delivery%20Date%3A%2004-Jan-2026%0ACurrent%20Status%3A%20%2AReady%2A%0A%0A%E2%9C%85%20Service%20update%20for%20information.%0A%0ABalance%20Amount%3A%20%E2%82%B9350%0A%0A%E2%80%94%20SMART%20TIMES%20SERVICE | Q3: =IFERROR(__xludf.DUMMYFUNCTION("IF(REGEXMATCH(LOWER(L3),""ready""), ""https://wa.me/91""&C3&""?text="" & ENCODEURL( ""📢 *SERVICE READY – READY FOR COLLECTION*"" & CHAR(10) & CHAR(10) & ""📌 *English*"" & CHAR(10) & ""Dear "" & B3 & "","" & CHAR(10) & ""Your watch service is completed"&" and ready for collection."" & CHAR(10) & ""Brand: "" & D3 & CHAR(10) & ""Problem: "" & F3 & CHAR(10) & ""Received Date: "" & TEXT(G3,""dd-mmm-yyyy"") & CHAR(10) & ""Ready Date: "" & TEXT(H3,""dd-mmm-yyyy"") & CHAR(10) & ""Balance Amount: ₹"" & K3 & CHAR("&"10) & CHAR(10) & ""📍 *Shop Address:*"" & CHAR(10) & ""SMART TIMES,"" & CHAR(10) & ""8/107, Pennagaram Main Road,"" & CHAR(10) & ""Next to R.C Church,"" & CHAR(10) & ""Dharmapuri – 636701"" & CHAR(10) & CHAR(10) & ""🗺 *Google Map:* https://maps.app.goo."&"gl/DpPkfna7HQttxYXn9"" & CHAR(10) & CHAR(10) & ""📌 *தமிழ்*"" & CHAR(10) & ""வணக்கம் "" & B3 & "","" & CHAR(10) & ""உங்கள் கடிகார சர்வீஸ் முடிந்து, பெற்றுக்கொள்ள தயாராக உள்ளது."" & CHAR(10) & ""தயவுசெய்து கடைக்கு வந்து பெற்றுக்கொள்ளவும்."" & CHAR(10) & "&"""பிராண்ட்: "" & D3 & CHAR(10) & ""பெறப்பட்ட தேதி: "" & TEXT(G3,""dd-mmm-yyyy"") & CHAR(10) & ""தயார் தேதி: "" & TEXT(H3,""dd-mmm-yyyy"") & CHAR(10) & ""மீதத் தொகை: ₹"" & K3 & CHAR(10) & CHAR(10) & ""🗺 *Google Map:* https://maps.app.goo.gl/DpPkfna7HQttx"&"YXn9"" & CHAR(10) & CHAR(10) & ""🙏 SMART TIMES SERVICE"" ), """") "),"https://wa.me/918015336933?text=%F0%9F%93%A2%20%2ASERVICE%20READY%20%E2%80%93%20READY%20FOR%20COLLECTION%2A%0A%0A%F0%9F%93%8C%20%2AEnglish%2A%0ADear%20MRS.SHANTHI%2C%0AYour%20watch%20service%20is%20completed%20and%20ready%20for%20collection.%0ABrand%3A%20"&"TITAN%0AProblem%3A%20SERVICE%0AReceived%20Date%3A%2001-Jan-2026%0AReady%20Date%3A%2004-Jan-2026%0ABalance%20Amount%3A%20%E2%82%B9350%0A%0A%F0%9F%93%8D%20%2AShop%20Address%3A%2A%0ASMART%20TIMES%2C%0A8%2F107%2C%20Pennagaram%20Main%20Road%2C%0ANext%20to%20R."&"C%20Church%2C%0ADharmapuri%20%E2%80%93%20636701%0A%0A%F0%9F%97%BA%20%2AGoogle%20Map%3A%2A%20https%3A%2F%2Fmaps.app.goo.gl%2FDpPkfna7HQttxYXn9%0A%0A%F0%9F%93%8C%20%2A%E0%AE%A4%E0%AE%AE%E0%AE%BF%E0%AE%B4%E0%AF%8D%2A%0A%E0%AE%B5%E0%AE%A3%E0%AE%95%E0%AF%8D%E0"&"%AE%95%E0%AE%AE%E0%AF%8D%20MRS.SHANTHI%2C%0A%E0%AE%89%E0%AE%99%E0%AF%8D%E0%AE%95%E0%AE%B3%E0%AF%8D%20%E0%AE%95%E0%AE%9F%E0%AE%BF%E0%AE%95%E0%AE%BE%E0%AE%B0%20%E0%AE%9A%E0%AE%B0%E0%AF%8D%E0%AE%B5%E0%AF%80%E0%AE%B8%E0%AF%8D%20%E0%AE%AE%E0%AF%81%E0%AE%9F%E0%"&"AE%BF%E0%AE%A8%E0%AF%8D%E0%AE%A4%E0%AF%81%2C%20%E0%AE%AA%E0%AF%86%E0%AE%B1%E0%AF%8D%E0%AE%B1%E0%AF%81%E0%AE%95%E0%AF%8D%E0%AE%95%E0%AF%8A%E0%AE%B3%E0%AF%8D%E0%AE%B3%20%E0%AE%A4%E0%AE%AF%E0%AE%BE%E0%AE%B0%E0%AE%BE%E0%AE%95%20%E0%AE%89%E0%AE%B3%E0%AF%8D%E0%"&"AE%B3%E0%AE%A4%E0%AF%81.%0A%E0%AE%A4%E0%AE%AF%E0%AE%B5%E0%AF%81%E0%AE%9A%E0%AF%86%E0%AE%AF%E0%AF%8D%E0%AE%A4%E0%AF%81%20%E0%AE%95%E0%AE%9F%E0%AF%88%E0%AE%95%E0%AF%8D%E0%AE%95%E0%AF%81%20%E0%AE%B5%E0%AE%A8%E0%AF%8D%E0%AE%A4%E0%AF%81%20%E0%AE%AA%E0%AF%86%E0"&"%AE%B1%E0%AF%8D%E0%AE%B1%E0%AF%81%E0%AE%95%E0%AF%8D%E0%AE%95%E0%AF%8A%E0%AE%B3%E0%AF%8D%E0%AE%B3%E0%AE%B5%E0%AF%81%E0%AE%AE%E0%AF%8D.%0A%E0%AE%AA%E0%AE%BF%E0%AE%B0%E0%AE%BE%E0%AE%A3%E0%AF%8D%E0%AE%9F%E0%AF%8D%3A%20TITAN%0A%E0%AE%AA%E0%AF%86%E0%AE%B1%E0%AE"&"%AA%E0%AF%8D%E0%AE%AA%E0%AE%9F%E0%AF%8D%E0%AE%9F%20%E0%AE%A4%E0%AF%87%E0%AE%A4%E0%AE%BF%3A%2001-Jan-2026%0A%E0%AE%A4%E0%AE%AF%E0%AE%BE%E0%AE%B0%E0%AF%8D%20%E0%AE%A4%E0%AF%87%E0%AE%A4%E0%AE%BF%3A%2004-Jan-2026%0A%E0%AE%AE%E0%AF%80%E0%AE%A4%E0%AE%A4%E0%AF%8"&"D%20%E0%AE%A4%E0%AF%8A%E0%AE%95%E0%AF%88%3A%20%E2%82%B9350%0A%0A%F0%9F%97%BA%20%2AGoogle%20Map%3A%2A%20https%3A%2F%2Fmaps.app.goo.gl%2FDpPkfna7HQttxYXn9%0A%0A%F0%9F%99%8F%20SMART%20TIMES%20SERVICE") -> https://wa.me/918015336933?text=%F0%9F%93%A2%20%2ASERVICE%20READY%20%E2%80%93%20READY%20FOR%20COLLECTION%2A%0A%0A%F0%9F%93%8C%20%2AEnglish%2A%0ADear%20MRS.SHANTHI%2C%0AYour%20watch%20service%20is%20completed%20and%20ready%20for%20collection.%0ABrand%3A%20TITAN%0AProblem%3A%20SERVICE%0AReceived%20Date%3A%2001-Jan-2026%0AReady%20Date%3A%2004-Jan-2026%0ABalance%20Amount%3A%20%E2%82%B9350%0A%0A%F0%9F%93%8D%20%2AShop%20Address%3A%2A%0ASMART%20TIMES%2C%0A8%2F107%2C%20Pennagaram%20Main%20Road%2C%0ANext%20to%20R.C%20Church%2C%0ADharmapuri%20%E2%80%93%20636701%0A%0A%F0%9F%97%BA%20%2AGoogle%20Map%3A%2A%20https%3A%2F%2Fmaps.app.goo.gl%2FDpPkfna7HQttxYXn9%0A%0A%F0%9F%93%8C%20%2A%E0%AE%A4%E0%AE%AE%E0%AE%BF%E0%AE%B4%E0%AF%8D%2A%0A%E0%AE%B5%E0%AE%A3%E0%AE%95%E0%AF%8D%E0%AE%95%E0%AE%AE%E0%AF%8D%20MRS.SHANTHI%2C%0A%E0%AE%89%E0%AE%99%E0%AF%8D%E0%AE%95%E0%AE%B3%E0%AF%8D%20%E0%AE%95%E0%AE%9F%E0%AE%BF%E0%AE%95%E0%AE%BE%E0%AE%B0%20%E0%AE%9A%E0%AE%B0%E0%AF%8D%E0%AE%B5%E0%AF%80%E0%AE%B8%E0%AF%8D%20%E0%AE%AE%E0%AF%81%E0%AE%9F%E0%AE%BF%E0%AE%A8%E0%AF%8D%E0%AE%A4%E0%AF%81%2C%20%E0%AE%AA%E0%AF%86%E0%AE%B1%E0%AF%8D%E0%AE%B1%E0%AF%81%E0%AE%95%E0%AF%8D%E0%AE%95%E0%AF%8A%E0%AE%B3%E0%AF%8D%E0%AE%B3%20%E0%AE%A4%E0%AE%AF%E0%AE%BE%E0%AE%B0%E0%AE%BE%E0%AE%95%20%E0%AE%89%E0%AE%B3%E0%AF%8D%E0%AE%B3%E0%AE%A4%E0%AF%81.%0A%E0%AE%A4%E0%AE%AF%E0%AE%B5%E0%AF%81%E0%AE%9A%E0%AF%86%E0%AE%AF%E0%AF%8D%E0%AE%A4%E0%AF%81%20%E0%AE%95%E0%AE%9F%E0%AF%88%E0%AE%95%E0%AF%8D%E0%AE%95%E0%AF%81%20%E0%AE%B5%E0%AE%A8%E0%AF%8D%E0%AE%A4%E0%AF%81%20%E0%AE%AA%E0%AF%86%E0%AE%B1%E0%AF%8D%E0%AE%B1%E0%AF%81%E0%AE%95%E0%AF%8D%E0%AE%95%E0%AF%8A%E0%AE%B3%E0%AF%8D%E0%AE%B3%E0%AE%B5%E0%AF%81%E0%AE%AE%E0%AF%8D.%0A%E0%AE%AA%E0%AE%BF%E0%AE%B0%E0%AE%BE%E0%AE%A3%E0%AF%8D%E0%AE%9F%E0%AF%8D%3A%20TITAN%0A%E0%AE%AA%E0%AF%86%E0%AE%B1%E0%AE%AA%E0%AF%8D%E0%AE%AA%E0%AE%9F%E0%AF%8D%E0%AE%9F%20%E0%AE%A4%E0%AF%87%E0%AE%A4%E0%AE%BF%3A%2001-Jan-2026%0A%E0%AE%A4%E0%AE%AF%E0%AE%BE%E0%AE%B0%E0%AF%8D%20%E0%AE%A4%E0%AF%87%E0%AE%A4%E0%AE%BF%3A%2004-Jan-2026%0A%E0%AE%AE%E0%AF%80%E0%AE%A4%E0%AE%A4%E0%AF%8D%20%E0%AE%A4%E0%AF%8A%E0%AE%95%E0%AF%88%3A%20%E2%82%B9350%0A%0A%F0%9F%97%BA%20%2AGoogle%20Map%3A%2A%20https%3A%2F%2Fmaps.app.goo.gl%2FDpPkfna7HQttxYXn9%0A%0A%F0%9F%99%8F%20SMART%20TIMES%20SERVICE | R3: =HYPERLINK(Q3,"🟢 SEND WHATSAPP") -> 🟢 SEND WHATSAPP | S3: =IFERROR(__xludf.DUMMYFUNCTION("SUM(ARRAYFORMULA( REGEXMATCH(LOWER(L2:L506),""pending|in progress"")* (H2:H506>TODAY())*1 )) "),0.0) -> 0
P4: =IF(O4="YES", "https://wa.me/?text=" & ENCODEURL( IF(OR(L4="Pending",L4="In Progress"), "⚠ *SERVICE ALERT – ATTENTION REQUIRED*" & CHAR(10) & CHAR(10), "📢 *SERVICE STATUS UPDATE*" & CHAR(10) & CHAR(10) ) & "Service ID: " & A4 & CHAR(10) & "Customer: " & B4 & CHAR(10) & "Mobile: " & C4 & CHAR(10) & "Brand: " & D4 & CHAR(10) & "Problem: " & F4 & CHAR(10) & CHAR(10) & "Received Date: " & TEXT(G4,"dd-mmm-yyyy") & CHAR(10) & "Expected Delivery Date: " & TEXT(H4,"dd-mmm-yyyy") & CHAR(10) & "Current Status: *" & L4 & "*" & CHAR(10) & CHAR(10) & IF(OR(L4="Pending",L4="In Progress"), "⚠ Please follow up immediately.", "✅ Service update for information." ) & CHAR(10) & CHAR(10) & "Balance Amount: ₹" & K4 & CHAR(10) & CHAR(10) & "— SMART TIMES SERVICE" ), "") | Q4: =IFERROR(__xludf.DUMMYFUNCTION("IF(REGEXMATCH(LOWER(L4),""ready""), ""https://wa.me/91""&C4&""?text="" & ENCODEURL( ""📢 *SERVICE READY – READY FOR COLLECTION*"" & CHAR(10) & CHAR(10) & ""📌 *English*"" & CHAR(10) & ""Dear "" & B4 & "","" & CHAR(10) & ""Your watch service is completed"&" and ready for collection."" & CHAR(10) & ""Brand: "" & D4 & CHAR(10) & ""Problem: "" & F4 & CHAR(10) & ""Received Date: "" & TEXT(G4,""dd-mmm-yyyy"") & CHAR(10) & ""Ready Date: "" & TEXT(H4,""dd-mmm-yyyy"") & CHAR(10) & ""Balance Amount: ₹"" & K4 & CHAR("&"10) & CHAR(10) & ""📍 *Shop Address:*"" & CHAR(10) & ""SMART TIMES,"" & CHAR(10) & ""8/107, Pennagaram Main Road,"" & CHAR(10) & ""Next to R.C Church,"" & CHAR(10) & ""Dharmapuri – 636701"" & CHAR(10) & CHAR(10) & ""🗺 *Google Map:* https://maps.app.goo."&"gl/DpPkfna7HQttxYXn9"" & CHAR(10) & CHAR(10) & ""📌 *தமிழ்*"" & CHAR(10) & ""வணக்கம் "" & B4 & "","" & CHAR(10) & ""உங்கள் கடிகார சர்வீஸ் முடிந்து, பெற்றுக்கொள்ள தயாராக உள்ளது."" & CHAR(10) & ""தயவுசெய்து கடைக்கு வந்து பெற்றுக்கொள்ளவும்."" & CHAR(10) & "&"""பிராண்ட்: "" & D4 & CHAR(10) & ""பெறப்பட்ட தேதி: "" & TEXT(G4,""dd-mmm-yyyy"") & CHAR(10) & ""தயார் தேதி: "" & TEXT(H4,""dd-mmm-yyyy"") & CHAR(10) & ""மீதத் தொகை: ₹"" & K4 & CHAR(10) & CHAR(10) & ""🗺 *Google Map:* https://maps.app.goo.gl/DpPkfna7HQttx"&"YXn9"" & CHAR(10) & CHAR(10) & ""🙏 SMART TIMES SERVICE"" ), """") "),"") | S4: =IFERROR(__xludf.DUMMYFUNCTION("IFERROR( TEXTJOIN(CHAR(10),TRUE, FILTER( ""🔴 ""&A2:A1011 &"" | Rec: ""&TEXT(G2:G1011,""dd-mmm"")& "" | Exp: ""&TEXT(H2:H1011,""dd-mmm""), (REGEXMATCH(LOWER(L2:L1011),""pending|in progress""))* (H2:H1011<TODAY()) ) ), ""None"" ) "),"🔴 2492 | Rec: 04-Jan | Exp: 14-Jan 🔴 2492 | Rec: 04-Jan | Exp: 14-Jan 🔴 2496 | Rec: 05-Jan | Exp: 09-Jan 🔴 2497 | Rec: 05-Jan | Exp: 09-Jan 🔴 2504 | Rec: 08-Jan | Exp: 11-Jan 🔴 2505 | Rec: 09-Jan | Exp: 13-Jan 🔴 2505 | Rec: 09-Jan | Exp: 13-Jan 🔴 "&"2507 | Rec: 11-Jan | Exp: 21-Jan 🔴 2508 | Rec: 11-Jan | Exp: 14-Jan 🔴 2509 | Rec: 12-Jan | Exp: 14-Jan 🔴 2510 | Rec: 12-Jan | Exp: 14-Jan") -> 🔴 2492 | Rec: 04-Jan | Exp: 14-Jan 🔴 2492 | Rec: 04-Jan | Exp: 14-Jan 🔴 2496 | Rec: 05-Jan | Exp: 09-Jan 🔴 2497 | Rec: 05-Jan | Exp: 09-Jan 🔴 2504 | Rec: 08-Jan | Exp: 11-Jan 🔴 2505 | Rec: 09-Jan | Exp: 13-Jan 🔴 2505 | Rec: 09-Jan | Exp: 13-Jan 🔴 2507 | Rec: 11-Jan | Exp: 21-Jan 🔴 2508 | Rec: 11-Jan | Exp: 14-Jan 🔴 2509 | Rec: 12-Jan | Exp: 14-Jan 🔴 2510 | Rec: 12-Jan | Exp: 14-Jan
A5: 2485 | B5: MR.KRISHNAN | C5: 9787723793 | D5: OTHER WATCHES | E5: LAMEX (YM\L) | F5: SERVIVE | G5: 46024 | H5: 46027 | I5: 250 | K5: =I5-J5 -> 250 | L5: Delivered | O5: YES | P5: =IF(O5="YES", "https://wa.me/?text=" & ENCODEURL( IF(OR(L5="Pending",L5="In Progress"), "⚠ *SERVICE ALERT – ATTENTION REQUIRED*" & CHAR(10) & CHAR(10), "📢 *SERVICE STATUS UPDATE*" & CHAR(10) & CHAR(10) ) & "Service ID: " & A5 & CHAR(10) & "Customer: " & B5 & CHAR(10) & "Mobile: " & C5 & CHAR(10) & "Brand: " & D5 & CHAR(10) & "Problem: " & F5 & CHAR(10) & CHAR(10) & "Received Date: " & TEXT(G5,"dd-mmm-yyyy") & CHAR(10) & "Expected Delivery Date: " & TEXT(H5,"dd-mmm-yyyy") & CHAR(10) & "Current Status: *" & L5 & "*" & CHAR(10) & CHAR(10) & IF(OR(L5="Pending",L5="In Progress"), "⚠ Please follow up immediately.", "✅ Service update for information." ) & CHAR(10) & CHAR(10) & "Balance Amount: ₹" & K5 & CHAR(10) & CHAR(10) & "— SMART TIMES SERVICE" ), "") -> https://wa.me/?text=%F0%9F%93%A2%20%2ASERVICE%20STATUS%20UPDATE%2A%0A%0AService%20ID%3A%202485%0ACustomer%3A%20MR.KRISHNAN%0AMobile%3A%209787723793%0ABrand%3A%20OTHER%20WATCHES%0AProblem%3A%20SERVIVE%0A%0AReceived%20Date%3A%2002-Jan-2026%0AExpected%20Delivery%20Date%3A%2005-Jan-2026%0ACurrent%20Status%3A%20%2ADelivered%2A%0A%0A%E2%9C%85%20Service%20update%20for%20information.%0A%0ABalance%20Amount%3A%20%E2%82%B9250%0A%0A%E2%80%94%20SMART%20TIMES%20SERVICE | Q5: =IFERROR(__xludf.DUMMYFUNCTION("IF(REGEXMATCH(LOWER(L5),""ready""), ""https://wa.me/91""&C5&""?text="" & ENCODEURL( ""📢 *SERVICE READY – READY FOR COLLECTION*"" & CHAR(10) & CHAR(10) & ""📌 *English*"" & CHAR(10) & ""Dear "" & B5 & "","" & CHAR(10) & ""Your watch service is completed"&" and ready for collection."" & CHAR(10) & ""Brand: "" & D5 & CHAR(10) & ""Problem: "" & F5 & CHAR(10) & ""Received Date: "" & TEXT(G5,""dd-mmm-yyyy"") & CHAR(10) & ""Ready Date: "" & TEXT(H5,""dd-mmm-yyyy"") & CHAR(10) & ""Balance Amount: ₹"" & K5 & CHAR("&"10) & CHAR(10) & ""📍 *Shop Address:*"" & CHAR(10) & ""SMART TIMES,"" & CHAR(10) & ""8/107, Pennagaram Main Road,"" & CHAR(10) & ""Next to R.C Church,"" & CHAR(10) & ""Dharmapuri – 636701"" & CHAR(10) & CHAR(10) & ""🗺 *Google Map:* https://maps.app.goo."&"gl/DpPkfna7HQttxYXn9"" & CHAR(10) & CHAR(10) & ""📌 *தமிழ்*"" & CHAR(10) & ""வணக்கம் "" & B5 & "","" & CHAR(10) & ""உங்கள் கடிகார சர்வீஸ் முடிந்து, பெற்றுக்கொள்ள தயாராக உள்ளது."" & CHAR(10) & ""தயவுசெய்து கடைக்கு வந்து பெற்றுக்கொள்ளவும்."" & CHAR(10) & "&"""பிராண்ட்: "" & D5 & CHAR(10) & ""பெறப்பட்ட தேதி: "" & TEXT(G5,""dd-mmm-yyyy"") & CHAR(10) & ""தயார் தேதி: "" & TEXT(H5,""dd-mmm-yyyy"") & CHAR(10) & ""மீதத் தொகை: ₹"" & K5 & CHAR(10) & CHAR(10) & ""🗺 *Google Map:* https://maps.app.goo.gl/DpPkfna7HQttx"&"YXn9"" & CHAR(10) & CHAR(10) & ""🙏 SMART TIMES SERVICE"" ), """") "),"") | R5: =HYPERLINK(Q5,"🟢 SEND WHATSAPP") -> 🟢 SEND WHATSAPP | S5: =IFERROR(__xludf.DUMMYFUNCTION("IFERROR( TEXTJOIN(CHAR(10),TRUE, FILTER( ""🟠 ""&A2:A1011 &"" | Rec: ""&TEXT(G2:G1011,""dd-mmm"")& "" | Exp: ""&TEXT(H2:H1011,""dd-mmm""), (REGEXMATCH(LOWER(L2:L1011),""pending|in progress""))* (H2:H1011=TODAY()) ) ), ""None"" ) "),"None") -> None
A6: 2486 | B6: MR.VENKAT RAMAN | C6: 94434635574 | D6: TITAN | E6: 1163(BM\G) | F6: SERVIVE | G6: 46024 | H6: 46027 | I6: 350 | K6: =I6-J6 -> 350 | L6: Delivered | O6: YES | P6: =IF(O6="YES", "https://wa.me/?text=" & ENCODEURL( IF(OR(L6="Pending",L6="In Progress"), "⚠ *SERVICE ALERT – ATTENTION REQUIRED*" & CHAR(10) & CHAR(10), "📢 *SERVICE STATUS UPDATE*" & CHAR(10) & CHAR(10) ) & "Service ID: " & A6 & CHAR(10) & "Customer: " & B6 & CHAR(10) & "Mobile: " & C6 & CHAR(10) & "Brand: " & D6 & CHAR(10) & "Problem: " & F6 & CHAR(10) & CHAR(10) & "Received Date: " & TEXT(G6,"dd-mmm-yyyy") & CHAR(10) & "Expected Delivery Date: " & TEXT(H6,"dd-mmm-yyyy") & CHAR(10) & "Current Status: *" & L6 & "*" & CHAR(10) & CHAR(10) & IF(OR(L6="Pending",L6="In Progress"), "⚠ Please follow up immediately.", "✅ Service update for information." ) & CHAR(10) & CHAR(10) & "Balance Amount: ₹" & K6 & CHAR(10) & CHAR(10) & "— SMART TIMES SERVICE" ), "") -> https://wa.me/?text=%F0%9F%93%A2%20%2ASERVICE%20STATUS%20UPDATE%2A%0A%0AService%20ID%3A%202486%0ACustomer%3A%20MR.VENKAT%20RAMAN%0AMobile%3A%2094434635574%0ABrand%3A%20TITAN%0AProblem%3A%20SERVIVE%0A%0AReceived%20Date%3A%2002-Jan-2026%0AExpected%20Delivery%20Date%3A%2005-Jan-2026%0ACurrent%20Status%3A%20%2ADelivered%2A%0A%0A%E2%9C%85%20Service%20update%20for%20information.%0A%0ABalance%20Amount%3A%20%E2%82%B9350%0A%0A%E2%80%94%20SMART%20TIMES%20SERVICE | Q6: =IFERROR(__xludf.DUMMYFUNCTION("IF(REGEXMATCH(LOWER(L6),""ready""), ""https://wa.me/91""&C6&""?text="" & ENCODEURL( ""📢 *SERVICE READY – READY FOR COLLECTION*"" & CHAR(10) & CHAR(10) & ""📌 *English*"" & CHAR(10) & ""Dear "" & B6 & "","" & CHAR(10) & ""Your watch service is completed"&" and ready for collection."" & CHAR(10) & ""Brand: "" & D6 & CHAR(10) & ""Problem: "" & F6 & CHAR(10) & ""Received Date: "" & TEXT(G6,""dd-mmm-yyyy"") & CHAR(10) & ""Ready Date: "" & TEXT(H6,""dd-mmm-yyyy"") & CHAR(10) & ""Balance Amount: ₹"" & K6 & CHAR("&"10) & CHAR(10) & ""📍 *Shop Address:*"" & CHAR(10) & ""SMART TIMES,"" & CHAR(10) & ""8/107, Pennagaram Main Road,"" & CHAR(10) & ""Next to R.C Church,"" & CHAR(10) & ""Dharmapuri – 636701"" & CHAR(10) & CHAR(10) & ""🗺 *Google Map:* https://maps.app.goo."&"gl/DpPkfna7HQttxYXn9"" & CHAR(10) & CHAR(10) & ""📌 *தமிழ்*"" & CHAR(10) & ""வணக்கம் "" & B6 & "","" & CHAR(10) & ""உங்கள் கடிகார சர்வீஸ் முடிந்து, பெற்றுக்கொள்ள தயாராக உள்ளது."" & CHAR(10) & ""தயவுசெய்து கடைக்கு வந்து பெற்றுக்கொள்ளவும்."" & CHAR(10) & "&"""பிராண்ட்: "" & D6 & CHAR(10) & ""பெறப்பட்ட தேதி: "" & TEXT(G6,""dd-mmm-yyyy"") & CHAR(10) & ""தயார் தேதி: "" & TEXT(H6,""dd-mmm-yyyy"") & CHAR(10) & ""மீதத் தொகை: ₹"" & K6 & CHAR(10) & CHAR(10) & ""🗺 *Google Map:* https://maps.app.goo.gl/DpPkfna7HQttx"&"YXn9"" & CHAR(10) & CHAR(10) & ""🙏 SMART TIMES SERVICE"" ), """") "),"") | R6: =HYPERLINK(Q6,"🟢 SEND WHATSAPP") -> 🟢 SEND WHATSAPP | S6: =IFERROR(__xludf.DUMMYFUNCTION("IFERROR( TEXTJOIN(CHAR(10),TRUE, FILTER( ""🔵 ""&A2:A1011 &"" | Rec: ""&TEXT(G2:G1011,""dd-mmm"")& "" | Exp: ""&TEXT(H2:H1011,""dd-mmm""), (REGEXMATCH(LOWER(L2:L1011),""pending|in progress""))* (H2:H1011>TODAY()) ) ), ""None"" ) "),"None") -> None
A7: =A6+1 -> 2487 | B7: MR.RAJABOOPATHI | C7: 9487038702 | D7: OTHER WATCHES | E7: INDIA POST(SL\G) | F7: RE SERVICE | G7: 46024 | H7: 46026 | I7: 0 | K7: =I7-J7 -> 0 | L7: Delivered | M7: 46035 | O7: YES | P7: =IF(O7="YES", "https://wa.me/?text=" & ENCODEURL( IF(OR(L7="Pending",L7="In Progress"), "⚠ *SERVICE ALERT – ATTENTION REQUIRED*" & CHAR(10) & CHAR(10), "📢 *SERVICE STATUS UPDATE*" & CHAR(10) & CHAR(10) ) & "Service ID: " & A7 & CHAR(10) & "Customer: " & B7 & CHAR(10) & "Mobile: " & C7 & CHAR(10) & "Brand: " & D7 & CHAR(10) & "Problem: " & F7 & CHAR(10) & CHAR(10) & "Received Date: " & TEXT(G7,"dd-mmm-yyyy") & CHAR(10) & "Expected Delivery Date: " & TEXT(H7,"dd-mmm-yyyy") & CHAR(10) & "Current Status: *" & L7 & "*" & CHAR(10) & CHAR(10) & IF(OR(L7="Pending",L7="In Progress"), "⚠ Please follow up immediately.", "✅ Service update for information." ) & CHAR(10) & CHAR(10) & "Balance Amount: ₹" & K7 & CHAR(10) & CHAR(10) & "— SMART TIMES SERVICE" ), "") -> https://wa.me/?text=%F0%9F%93%A2%20%2ASERVICE%20STATUS%20UPDATE%2A%0A%0AService%20ID%3A%202487%0ACustomer%3A%20MR.RAJABOOPATHI%0AMobile%3A%209487038702%0ABrand%3A%20OTHER%20WATCHES%0AProblem%3A%20RE%20SERVICE%0A%0AReceived%20Date%3A%2002-Jan-2026%0AExpected%20Delivery%20Date%3A%2004-Jan-2026%0ACurrent%20Status%3A%20%2ADelivered%2A%0A%0A%E2%9C%85%20Service%20update%20for%20information.%0A%0ABalance%20Amount%3A%20%E2%82%B90%0A%0A%E2%80%94%20SMART%20TIMES%20SERVICE | Q7: =IFERROR(__xludf.DUMMYFUNCTION("IF(REGEXMATCH(LOWER(L7),""ready""), ""https://wa.me/91""&C7&""?text="" & ENCODEURL( ""📢 *SERVICE READY – READY FOR COLLECTION*"" & CHAR(10) & CHAR(10) & ""📌 *English*"" & CHAR(10) & ""Dear "" & B7 & "","" & CHAR(10) & ""Your watch service is completed"&" and ready for collection."" & CHAR(10) & ""Brand: "" & D7 & CHAR(10) & ""Problem: "" & F7 & CHAR(10) & ""Received Date: "" & TEXT(G7,""dd-mmm-yyyy"") & CHAR(10) & ""Ready Date: "" & TEXT(H7,""dd-mmm-yyyy"") & CHAR(10) & ""Balance Amount: ₹"" & K7 & CHAR("&"10) & CHAR(10) & ""📍 *Shop Address:*"" & CHAR(10) & ""SMART TIMES,"" & CHAR(10) & ""8/107, Pennagaram Main Road,"" & CHAR(10) & ""Next to R.C Church,"" & CHAR(10) & ""Dharmapuri – 636701"" & CHAR(10) & CHAR(10) & ""🗺 *Google Map:* https://maps.app.goo."&"gl/DpPkfna7HQttxYXn9"" & CHAR(10) & CHAR(10) & ""📌 *தமிழ்*"" & CHAR(10) & ""வணக்கம் "" & B7 & "","" & CHAR(10) & ""உங்கள் கடிகார சர்வீஸ் முடிந்து, பெற்றுக்கொள்ள தயாராக உள்ளது."" & CHAR(10) & ""தயவுசெய்து கடைக்கு வந்து பெற்றுக்கொள்ளவும்."" & CHAR(10) & "&"""பிராண்ட்: "" & D7 & CHAR(10) & ""பெறப்பட்ட தேதி: "" & TEXT(G7,""dd-mmm-yyyy"") & CHAR(10) & ""தயார் தேதி: "" & TEXT(H7,""dd-mmm-yyyy"") & CHAR(10) & ""மீதத் தொகை: ₹"" & K7 & CHAR(10) & CHAR(10) & ""🗺 *Google Map:* https://maps.app.goo.gl/DpPkfna7HQttx"&"YXn9"" & CHAR(10) & CHAR(10) & ""🙏 SMART TIMES SERVICE"" ), """") "),"") | R7: =HYPERLINK(Q7,"🟢 SEND WHATSAPP") -> 🟢 SEND WHATSAPP | S7: ="https://wa.me/?text="&ENCODEURL( "📊 SERVICE STATUS SUMMARY"&CHAR(10)&CHAR(10)& "🔴 OVERDUE"&CHAR(10)&S4&CHAR(10)&CHAR(10)& "🟠 DUE TODAY"&CHAR(10)&S5&CHAR(10)&CHAR(10)& "🔵 REMAINING"&CHAR(10)&S6&CHAR(10)&CHAR(10)& "— SMART TIMES SERVICE" ) -> https://wa.me/?text=%F0%9F%93%8A%20SERVICE%20STATUS%20SUMMARY%0A%0A%F0%9F%94%B4%20OVERDUE%0A%F0%9F%94%B4%202492%20%7C%20Rec%3A%2004-Jan%20%7C%20Exp%3A%2014-Jan%0A%F0%9F%94%B4%202492%20%7C%20Rec%3A%2004-Jan%20%7C%20Exp%3A%2014-Jan%0A%F0%9F%94%B4%202496%20%7C%20Rec%3A%2005-Jan%20%7C%20Exp%3A%2009-Jan%0A%F0%9F%94%B4%202497%20%7C%20Rec%3A%2005-Jan%20%7C%20Exp%3A%2009-Jan%0A%F0%9F%94%B4%202504%20%7C%20Rec%3A%2008-Jan%20%7C%20Exp%3A%2011-Jan%0A%F0%9F%94%B4%202505%20%7C%20Rec%3A%2009-Jan%20%7C%20Exp%3A%2013-Jan%0A%F0%9F%94%B4%202505%20%7C%20Rec%3A%2009-Jan%20%7C%20Exp%3A%2013-Jan%0A%F0%9F%94%B4%202507%20%7C%20Rec%3A%2011-Jan%20%7C%20Exp%3A%2021-Jan%0A%F0%9F%94%B4%202508%20%7C%20Rec%3A%2011-Jan%20%7C%20Exp%3A%2014-Jan%0A%F0%9F%94%B4%202509%20%7C%20Rec%3A%2012-Jan%20%7C%20Exp%3A%2014-Jan%0A%F0%9F%94%B4%202510%20%7C%20Rec%3A%2012-Jan%20%7C%20Exp%3A%2014-Jan%0A%0A%F0%9F%9F%A0%20DUE%20TODAY%0ANone%0A%0A%F0%9F%94%B5%20REMAINING%0ANone%0A%0A%E2%80%94%20SMART%20TIMES%20SERVICE
A8: =A7+1 -> 2488 | B8: MR.SHANKAR | C8: 9443264508 | D8: TITAN | E8: 1955(YM\G) | F8: MG | G8: 46024 | H8: 46025 | K8: =I8-J8 -> 0 | L8: Delivered | M8: 46029 | P8: =IF(O8="YES", "https://wa.me/?text=" & ENCODEURL( IF(OR(L8="Pending",L8="In Progress"), "⚠ *SERVICE ALERT – ATTENTION REQUIRED*" & CHAR(10) & CHAR(10), "📢 *SERVICE STATUS UPDATE*" & CHAR(10) & CHAR(10) ) & "Service ID: " & A8 & CHAR(10) & "Customer: " & B8 & CHAR(10) & "Mobile: " & C8 & CHAR(10) & "Brand: " & D8 & CHAR(10) & "Problem: " & F8 & CHAR(10) & CHAR(10) & "Received Date: " & TEXT(G8,"dd-mmm-yyyy") & CHAR(10) & "Expected Delivery Date: " & TEXT(H8,"dd-mmm-yyyy") & CHAR(10) & "Current Status: *" & L8 & "*" & CHAR(10) & CHAR(10) & IF(OR(L8="Pending",L8="In Progress"), "⚠ Please follow up immediately.", "✅ Service update for information." ) & CHAR(10) & CHAR(10) & "Balance Amount: ₹" & K8 & CHAR(10) & CHAR(10) & "— SMART TIMES SERVICE" ), "") | Q8: =IFERROR(__xludf.DUMMYFUNCTION("IF(REGEXMATCH(LOWER(L8),""ready""), ""https://wa.me/91""&C8&""?text="" & ENCODEURL( ""📢 *SERVICE READY – READY FOR COLLECTION*"" & CHAR(10) & CHAR(10) & ""📌 *English*"" & CHAR(10) & ""Dear "" & B8 & "","" & CHAR(10) & ""Your watch service is completed"&" and ready for collection."" & CHAR(10) & ""Brand: "" & D8 & CHAR(10) & ""Problem: "" & F8 & CHAR(10) & ""Received Date: "" & TEXT(G8,""dd-mmm-yyyy"") & CHAR(10) & ""Ready Date: "" & TEXT(H8,""dd-mmm-yyyy"") & CHAR(10) & ""Balance Amount: ₹"" & K8 & CHAR("&"10) & CHAR(10) & ""📍 *Shop Address:*"" & CHAR(10) & ""SMART TIMES,"" & CHAR(10) & ""8/107, Pennagaram Main Road,"" & CHAR(10) & ""Next to R.C Church,"" & CHAR(10) & ""Dharmapuri – 636701"" & CHAR(10) & CHAR(10) & ""🗺 *Google Map:* https://maps.app.goo."&"gl/DpPkfna7HQttxYXn9"" & CHAR(10) & CHAR(10) & ""📌 *தமிழ்*"" & CHAR(10) & ""வணக்கம் "" & B8 & "","" & CHAR(10) & ""உங்கள் கடிகார சர்வீஸ் முடிந்து, பெற்றுக்கொள்ள தயாராக உள்ளது."" & CHAR(10) & ""தயவுசெய்து கடைக்கு வந்து பெற்றுக்கொள்ளவும்."" & CHAR(10) & "&"""பிராண்ட்: "" & D8 & CHAR(10) & ""பெறப்பட்ட தேதி: "" & TEXT(G8,""dd-mmm-yyyy"") & CHAR(10) & ""தயார் தேதி: "" & TEXT(H8,""dd-mmm-yyyy"") & CHAR(10) & ""மீதத் தொகை: ₹"" & K8 & CHAR(10) & CHAR(10) & ""🗺 *Google Map:* https://maps.app.goo.gl/DpPkfna7HQttx"&"YXn9"" & CHAR(10) & CHAR(10) & ""🙏 SMART TIMES SERVICE"" ), """") "),"") | R8: =HYPERLINK(Q8,"🟢 SEND WHATSAPP") -> 🟢 SEND WHATSAPP | S8: =HYPERLINK(S7,"🟢 SEND WHATSAPP") -> 🟢 SEND WHATSAPP
A10: 2489 | B10: MR.PERIYA SWMAY | C10: 9791280413 | D10: SONATA | E10: 77083(NM\G) | F10: MG+CROWN BUTTON | G10: 46025 | H10: 46026 | K10: =I10-J10 -> 0 | L10: Ready | O10: YES | P10: =IF(O10="YES", "https://wa.me/?text=" & ENCODEURL( IF(OR(L10="Pending",L10="In Progress"), "⚠ *SERVICE ALERT – ATTENTION REQUIRED*" & CHAR(10) & CHAR(10), "📢 *SERVICE STATUS UPDATE*" & CHAR(10) & CHAR(10) ) & "Service ID: " & A10 & CHAR(10) & "Customer: " & B10 & CHAR(10) & "Mobile: " & C10 & CHAR(10) & "Brand: " & D10 & CHAR(10) & "Problem: " & F10 & CHAR(10) & CHAR(10) & "Received Date: " & TEXT(G10,"dd-mmm-yyyy") & CHAR(10) & "Expected Delivery Date: " & TEXT(H10,"dd-mmm-yyyy") & CHAR(10) & "Current Status: *" & L10 & "*" & CHAR(10) & CHAR(10) & IF(OR(L10="Pending",L10="In Progress"), "⚠ Please follow up immediately.", "✅ Service update for information." ) & CHAR(10) & CHAR(10) & "Balance Amount: ₹" & K10 & CHAR(10) & CHAR(10) & "— SMART TIMES SERVICE" ), "") -> https://wa.me/?text=%F0%9F%93%A2%20%2ASERVICE%20STATUS%20UPDATE%2A%0A%0AService%20ID%3A%202489%0ACustomer%3A%20MR.PERIYA%20SWMAY%0AMobile%3A%209791280413%0ABrand%3A%20SONATA%0AProblem%3A%20MG%2BCROWN%20BUTTON%0A%0AReceived%20Date%3A%2003-Jan-2026%0AExpected%20Delivery%20Date%3A%2004-Jan-2026%0ACurrent%20Status%3A%20%2AReady%2A%0A%0A%E2%9C%85%20Service%20update%20for%20information.%0A%0ABalance%20Amount%3A%20%E2%82%B90%0A%0A%E2%80%94%20SMART%20TIMES%20SERVICE | Q10: =IFERROR(__xludf.DUMMYFUNCTION("IF(REGEXMATCH(LOWER(L10),""ready""), ""https://wa.me/91""&C10&""?text="" & ENCODEURL( ""📢 *SERVICE READY – READY FOR COLLECTION*"" & CHAR(10) & CHAR(10) & ""📌 *English*"" & CHAR(10) & ""Dear "" & B10 & "","" & CHAR(10) & ""Your watch service is comple"&"ted and ready for collection."" & CHAR(10) & ""Brand: "" & D10 & CHAR(10) & ""Problem: "" & F10 & CHAR(10) & ""Received Date: "" & TEXT(G10,""dd-mmm-yyyy"") & CHAR(10) & ""Ready Date: "" & TEXT(H10,""dd-mmm-yyyy"") & CHAR(10) & ""Balance Amount: ₹"" & K10"&" & CHAR(10) & CHAR(10) & ""📍 *Shop Address:*"" & CHAR(10) & ""SMART TIMES,"" & CHAR(10) & ""8/107, Pennagaram Main Road,"" & CHAR(10) & ""Next to R.C Church,"" & CHAR(10) & ""Dharmapuri – 636701"" & CHAR(10) & CHAR(10) & ""🗺 *Google Map:* https://maps."&"app.goo.gl/DpPkfna7HQttxYXn9"" & CHAR(10) & CHAR(10) & ""📌 *தமிழ்*"" & CHAR(10) & ""வணக்கம் "" & B10 & "","" & CHAR(10) & ""உங்கள் கடிகார சர்வீஸ் முடிந்து, பெற்றுக்கொள்ள தயாராக உள்ளது."" & CHAR(10) & ""தயவுசெய்து கடைக்கு வந்து பெற்றுக்கொள்ளவும்."" & CHA"&"R(10) & ""பிராண்ட்: "" & D10 & CHAR(10) & ""பெறப்பட்ட தேதி: "" & TEXT(G10,""dd-mmm-yyyy"") & CHAR(10) & ""தயார் தேதி: "" & TEXT(H10,""dd-mmm-yyyy"") & CHAR(10) & ""மீதத் தொகை: ₹"" & K10 & CHAR(10) & CHAR(10) & ""🗺 *Google Map:* https://maps.app.goo.gl/D"&"pPkfna7HQttxYXn9"" & CHAR(10) & CHAR(10) & ""🙏 SMART TIMES SERVICE"" ), """") "),"https://wa.me/919791280413?text=%F0%9F%93%A2%20%2ASERVICE%20READY%20%E2%80%93%20READY%20FOR%20COLLECTION%2A%0A%0A%F0%9F%93%8C%20%2AEnglish%2A%0ADear%20MR.PERIYA%20SWMAY%2C%0AYour%20watch%20service%20is%20completed%20and%20ready%20for%20collection.%0ABrand"&"%3A%20SONATA%0AProblem%3A%20MG%2BCROWN%20BUTTON%0AReceived%20Date%3A%2003-Jan-2026%0AReady%20Date%3A%2004-Jan-2026%0ABalance%20Amount%3A%20%E2%82%B90%0A%0A%F0%9F%93%8D%20%2AShop%20Address%3A%2A%0ASMART%20TIMES%2C%0A8%2F107%2C%20Pennagaram%20Main%20Road%2C"&"%0ANext%20to%20R.C%20Church%2C%0ADharmapuri%20%E2%80%93%20636701%0A%0A%F0%9F%97%BA%20%2AGoogle%20Map%3A%2A%20https%3A%2F%2Fmaps.app.goo.gl%2FDpPkfna7HQttxYXn9%0A%0A%F0%9F%93%8C%20%2A%E0%AE%A4%E0%AE%AE%E0%AE%BF%E0%AE%B4%E0%AF%8D%2A%0A%E0%AE%B5%E0%AE%A3%E0%"&"AE%95%E0%AF%8D%E0%AE%95%E0%AE%AE%E0%AF%8D%20MR.PERIYA%20SWMAY%2C%0A%E0%AE%89%E0%AE%99%E0%AF%8D%E0%AE%95%E0%AE%B3%E0%AF%8D%20%E0%AE%95%E0%AE%9F%E0%AE%BF%E0%AE%95%E0%AE%BE%E0%AE%B0%20%E0%AE%9A%E0%AE%B0%E0%AF%8D%E0%AE%B5%E0%AF%80%E0%AE%B8%E0%AF%8D%20%E0%AE%A"&"E%E0%AF%81%E0%AE%9F%E0%AE%BF%E0%AE%A8%E0%AF%8D%E0%AE%A4%E0%AF%81%2C%20%E0%AE%AA%E0%AF%86%E0%AE%B1%E0%AF%8D%E0%AE%B1%E0%AF%81%E0%AE%95%E0%AF%8D%E0%AE%95%E0%AF%8A%E0%AE%B3%E0%AF%8D%E0%AE%B3%20%E0%AE%A4%E0%AE%AF%E0%AE%BE%E0%AE%B0%E0%AE%BE%E0%AE%95%20%E0%AE%8"&"9%E0%AE%B3%E0%AF%8D%E0%AE%B3%E0%AE%A4%E0%AF%81.%0A%E0%AE%A4%E0%AE%AF%E0%AE%B5%E0%AF%81%E0%AE%9A%E0%AF%86%E0%AE%AF%E0%AF%8D%E0%AE%A4%E0%AF%81%20%E0%AE%95%E0%AE%9F%E0%AF%88%E0%AE%95%E0%AF%8D%E0%AE%95%E0%AF%81%20%E0%AE%B5%E0%AE%A8%E0%AF%8D%E0%AE%A4%E0%AF%81%"&"20%E0%AE%AA%E0%AF%86%E0%AE%B1%E0%AF%8D%E0%AE%B1%E0%AF%81%E0%AE%95%E0%AF%8D%E0%AE%95%E0%AF%8A%E0%AE%B3%E0%AF%8D%E0%AE%B3%E0%AE%B5%E0%AF%81%E0%AE%AE%E0%AF%8D.%0A%E0%AE%AA%E0%AE%BF%E0%AE%B0%E0%AE%BE%E0%AE%A3%E0%AF%8D%E0%AE%9F%E0%AF%8D%3A%20SONATA%0A%E0%AE%AA"&"%E0%AF%86%E0%AE%B1%E0%AE%AA%E0%AF%8D%E0%AE%AA%E0%AE%9F%E0%AF%8D%E0%AE%9F%20%E0%AE%A4%E0%AF%87%E0%AE%A4%E0%AE%BF%3A%2003-Jan-2026%0A%E0%AE%A4%E0%AE%AF%E0%AE%BE%E0%AE%B0%E0%AF%8D%20%E0%AE%A4%E0%AF%87%E0%AE%A4%E0%AE%BF%3A%2004-Jan-2026%0A%E0%AE%AE%E0%AF%80%E"&"0%AE%A4%E0%AE%A4%E0%AF%8D%20%E0%AE%A4%E0%AF%8A%E0%AE%95%E0%AF%88%3A%20%E2%82%B90%0A%0A%F0%9F%97%BA%20%2AGoogle%20Map%3A%2A%20https%3A%2F%2Fmaps.app.goo.gl%2FDpPkfna7HQttxYXn9%0A%0A%F0%9F%99%8F%20SMART%20TIMES%20SERVICE") -> https://wa.me/919791280413?text=%F0%9F%93%A2%20%2ASERVICE%20READY%20%E2%80%93%20READY%20FOR%20COLLECTION%2A%0A%0A%F0%9F%93%8C%20%2AEnglish%2A%0ADear%20MR.PERIYA%20SWMAY%2C%0AYour%20watch%20service%20is%20completed%20and%20ready%20for%20collection.%0ABrand%3A%20SONATA%0AProblem%3A%20MG%2BCROWN%20BUTTON%0AReceived%20Date%3A%2003-Jan-2026%0AReady%20Date%3A%2004-Jan-2026%0ABalance%20Amount%3A%20%E2%82%B90%0A%0A%F0%9F%93%8D%20%2AShop%20Address%3A%2A%0ASMART%20TIMES%2C%0A8%2F107%2C%20Pennagaram%20Main%20Road%2C%0ANext%20to%20R.C%20Church%2C%0ADharmapuri%20%E2%80%93%20636701%0A%0A%F0%9F%97%BA%20%2AGoogle%20Map%3A%2A%20https%3A%2F%2Fmaps.app.goo.gl%2FDpPkfna7HQttxYXn9%0A%0A%F0%9F%93%8C%20%2A%E0%AE%A4%E0%AE%AE%E0%AE%BF%E0%AE%B4%E0%AF%8D%2A%0A%E0%AE%B5%E0%AE%A3%E0%AE%95%E0%AF%8D%E0%AE%95%E0%AE%AE%E0%AF%8D%20MR.PERIYA%20SWMAY%2C%0A%E0%AE%89%E0%AE%99%E0%AF%8D%E0%AE%95%E0%AE%B3%E0%AF%8D%20%E0%AE%95%E0%AE%9F%E0%AE%BF%E0%AE%95%E0%AE%BE%E0%AE%B0%20%E0%AE%9A%E0%AE%B0%E0%AF%8D%E0%AE%B5%E0%AF%80%E0%AE%B8%E0%AF%8D%20%E0%AE%AE%E0%AF%81%E0%AE%9F%E0%AE%BF%E0%AE%A8%E0%AF%8D%E0%AE%A4%E0%AF%81%2C%20%E0%AE%AA%E0%AF%86%E0%AE%B1%E0%AF%8D%E0%AE%B1%E0%AF%81%E0%AE%95%E0%AF%8D%E0%AE%95%E0%AF%8A%E0%AE%B3%E0%AF%8D%E0%AE%B3%20%E0%AE%A4%E0%AE%AF%E0%AE%BE%E0%AE%B0%E0%AE%BE%E0%AE%95%20%E0%AE%89%E0%AE%B3%E0%AF%8D%E0%AE%B3%E0%AE%A4%E0%AF%81.%0A%E0%AE%A4%E0%AE%AF%E0%AE%B5%E0%AF%81%E0%AE%9A%E0%AF%86%E0%AE%AF%E0%AF%8D%E0%AE%A4%E0%AF%81%20%E0%AE%95%E0%AE%9F%E0%AF%88%E0%AE%95%E0%AF%8D%E0%AE%95%E0%AF%81%20%E0%AE%B5%E0%AE%A8%E0%AF%8D%E0%AE%A4%E0%AF%81%20%E0%AE%AA%E0%AF%86%E0%AE%B1%E0%AF%8D%E0%AE%B1%E0%AF%81%E0%AE%95%E0%AF%8D%E0%AE%95%E0%AF%8A%E0%AE%B3%E0%AF%8D%E0%AE%B3%E0%AE%B5%E0%AF%81%E0%AE%AE%E0%AF%8D.%0A%E0%AE%AA%E0%AE%BF%E0%AE%B0%E0%AE%BE%E0%AE%A3%E0%AF%8D%E0%AE%9F%E0%AF%8D%3A%20SONATA%0A%E0%AE%AA%E0%AF%86%E0%AE%B1%E0%AE%AA%E0%AF%8D%E0%AE%AA%E0%AE%9F%E0%AF%8D%E0%AE%9F%20%E0%AE%A4%E0%AF%87%E0%AE%A4%E0%AE%BF%3A%2003-Jan-2026%0A%E0%AE%A4%E0%AE%AF%E0%AE%BE%E0%AE%B0%E0%AF%8D%20%E0%AE%A4%E0%AF%87%E0%AE%A4%E0%AE%BF%3A%2004-Jan-2026%0A%E0%AE%AE%E0%AF%80%E0%AE%A4%E0%AE%A4%E0%AF%8D%20%E0%AE%A4%E0%AF%8A%E0%AE%95%E0%AF%88%3A%20%E2%82%B90%0A%0A%F0%9F%97%BA%20%2AGoogle%20Map%3A%2A%20https%3A%2F%2Fmaps.app.goo.gl%2FDpPkfna7HQttxYXn9%0A%0A%F0%9F%99%8F%20SMART%20TIMES%20SERVICE | R10: =HYPERLINK(Q10,"🟢 SEND WHATSAPP") -> 🟢 SEND WHATSAPP
A11: =A10+1 -> 2490 | B11: MR.MANDHARAN | C11: 8344720406 | D11: OTHER WATCHES | E11: HMT AUTOMATIC | F11: KEY BUTTON | G11: 46025 | H11: 46026 | K11: =I11-J11 -> 0 | L11: Returned | M11: 46027 | N11: RETURNED TO THE CUSTOMER WITHOUT REPAIR | O11: YES | P11: =IF(O11="YES", "https://wa.me/?text=" & ENCODEURL( IF(OR(L11="Pending",L11="In Progress"), "⚠ *SERVICE ALERT – ATTENTION REQUIRED*" & CHAR(10) & CHAR(10), "📢 *SERVICE STATUS UPDATE*" & CHAR(10) & CHAR(10) ) & "Service ID: " & A11 & CHAR(10) & "Customer: " & B11 & CHAR(10) & "Mobile: " & C11 & CHAR(10) & "Brand: " & D11 & CHAR(10) & "Problem: " & F11 & CHAR(10) & CHAR(10) & "Received Date: " & TEXT(G11,"dd-mmm-yyyy") & CHAR(10) & "Expected Delivery Date: " & TEXT(H11,"dd-mmm-yyyy") & CHAR(10) & "Current Status: *" & L11 & "*" & CHAR(10) & CHAR(10) & IF(OR(L11="Pending",L11="In Progress"), "⚠ Please follow up immediately.", "✅ Service update for information." ) & CHAR(10) & CHAR(10) & "Balance Amount: ₹" & K11 & CHAR(10) & CHAR(10) & "— SMART TIMES SERVICE" ), "") -> https://wa.me/?text=%F0%9F%93%A2%20%2ASERVICE%20STATUS%20UPDATE%2A%0A%0AService%20ID%3A%202490%0ACustomer%3A%20MR.MANDHARAN%0AMobile%3A%208344720406%0ABrand%3A%20OTHER%20WATCHES%0AProblem%3A%20KEY%20BUTTON%0A%0AReceived%20Date%3A%2003-Jan-2026%0AExpected%20Delivery%20Date%3A%2004-Jan-2026%0ACurrent%20Status%3A%20%2AReturned%2A%0A%0A%E2%9C%85%20Service%20update%20for%20information.%0A%0ABalance%20Amount%3A%20%E2%82%B90%0A%0A%E2%80%94%20SMART%20TIMES%20SERVICE | Q11: =IFERROR(__xludf.DUMMYFUNCTION("IF(REGEXMATCH(LOWER(L11),""ready""), ""https://wa.me/91""&C11&""?text="" & ENCODEURL( ""📢 *SERVICE READY – READY FOR COLLECTION*"" & CHAR(10) & CHAR(10) & ""📌 *English*"" & CHAR(10) & ""Dear "" & B11 & "","" & CHAR(10) & ""Your watch service is comple"&"ted and ready for collection."" & CHAR(10) & ""Brand: "" & D11 & CHAR(10) & ""Problem: "" & F11 & CHAR(10) & ""Received Date: "" & TEXT(G11,""dd-mmm-yyyy"") & CHAR(10) & ""Ready Date: "" & TEXT(H11,""dd-mmm-yyyy"") & CHAR(10) & ""Balance Amount: ₹"" & K11"&" & CHAR(10) & CHAR(10) & ""📍 *Shop Address:*"" & CHAR(10) & ""SMART TIMES,"" & CHAR(10) & ""8/107, Pennagaram Main Road,"" & CHAR(10) & ""Next to R.C Church,"" & CHAR(10) & ""Dharmapuri – 636701"" & CHAR(10) & CHAR(10) & ""🗺 *Google Map:* https://maps."&"app.goo.gl/DpPkfna7HQttxYXn9"" & CHAR(10) & CHAR(10) & ""📌 *தமிழ்*"" & CHAR(10) & ""வணக்கம் "" & B11 & "","" & CHAR(10) & ""உங்கள் கடிகார சர்வீஸ் முடிந்து, பெற்றுக்கொள்ள தயாராக உள்ளது."" & CHAR(10) & ""தயவுசெய்து கடைக்கு வந்து பெற்றுக்கொள்ளவும்."" & CHA"&"R(10) & ""பிராண்ட்: "" & D11 & CHAR(10) & ""பெறப்பட்ட தேதி: "" & TEXT(G11,""dd-mmm-yyyy"") & CHAR(10) & ""தயார் தேதி: "" & TEXT(H11,""dd-mmm-yyyy"") & CHAR(10) & ""மீதத் தொகை: ₹"" & K11 & CHAR(10) & CHAR(10) & ""🗺 *Google Map:* https://maps.app.goo.gl/D"&"pPkfna7HQttxYXn9"" & CHAR(10) & CHAR(10) & ""🙏 SMART TIMES SERVICE"" ), """") "),"") | R11: =HYPERLINK(Q11,"🟢 SEND WHATSAPP") -> 🟢 SEND WHATSAPP
A12: =A11+1 -> 2491 | B12: MR.NAVEEN KUMAR | C12: 8248071974 | D12: SMART WATCH | E12: FASTRACK PP03 | F12: BATTERY DRAIN | G12: 46025 | H12: 46029 | I12: 500 | K12: =I12-J12 -> 500 | L12: Delivered | M12: 46029 | O12: YES | P12: =IF(O12="YES", "https://wa.me/?text=" & ENCODEURL( IF(OR(L12="Pending",L12="In Progress"), "⚠ *SERVICE ALERT – ATTENTION REQUIRED*" & CHAR(10) & CHAR(10), "📢 *SERVICE STATUS UPDATE*" & CHAR(10) & CHAR(10) ) & "Service ID: " & A12 & CHAR(10) & "Customer: " & B12 & CHAR(10) & "Mobile: " & C12 & CHAR(10) & "Brand: " & D12 & CHAR(10) & "Problem: " & F12 & CHAR(10) & CHAR(10) & "Received Date: " & TEXT(G12,"dd-mmm-yyyy") & CHAR(10) & "Expected Delivery Date: " & TEXT(H12,"dd-mmm-yyyy") & CHAR(10) & "Current Status: *" & L12 & "*" & CHAR(10) & CHAR(10) & IF(OR(L12="Pending",L12="In Progress"), "⚠ Please follow up immediately.", "✅ Service update for information." ) & CHAR(10) & CHAR(10) & "Balance Amount: ₹" & K12 & CHAR(10) & CHAR(10) & "— SMART TIMES SERVICE" ), "") -> https://wa.me/?text=%F0%9F%93%A2%20%2ASERVICE%20STATUS%20UPDATE%2A%0A%0AService%20ID%3A%202491%0ACustomer%3A%20MR.NAVEEN%20KUMAR%0AMobile%3A%208248071974%0ABrand%3A%20SMART%20WATCH%0AProblem%3A%20BATTERY%20DRAIN%0A%0AReceived%20Date%3A%2003-Jan-2026%0AExpected%20Delivery%20Date%3A%2007-Jan-2026%0ACurrent%20Status%3A%20%2ADelivered%2A%0A%0A%E2%9C%85%20Service%20update%20for%20information.%0A%0ABalance%20Amount%3A%20%E2%82%B9500%0A%0A%E2%80%94%20SMART%20TIMES%20SERVICE | Q12: =IFERROR(__xludf.DUMMYFUNCTION("IF(REGEXMATCH(LOWER(L12),""ready""), ""https://wa.me/91""&C12&""?text="" & ENCODEURL( ""📢 *SERVICE READY – READY FOR COLLECTION*"" & CHAR(10) & CHAR(10) & ""📌 *English*"" & CHAR(10) & ""Dear "" & B12 & "","" & CHAR(10) & ""Your watch service is comple"&"ted and ready for collection."" & CHAR(10) & ""Brand: "" & D12 & CHAR(10) & ""Problem: "" & F12 & CHAR(10) & ""Received Date: "" & TEXT(G12,""dd-mmm-yyyy"") & CHAR(10) & ""Ready Date: "" & TEXT(H12,""dd-mmm-yyyy"") & CHAR(10) & ""Balance Amount: ₹"" & K12"&" & CHAR(10) & CHAR(10) & ""📍 *Shop Address:*"" & CHAR(10) & ""SMART TIMES,"" & CHAR(10) & ""8/107, Pennagaram Main Road,"" & CHAR(10) & ""Next to R.C Church,"" & CHAR(10) & ""Dharmapuri – 636701"" & CHAR(10) & CHAR(10) & ""🗺 *Google Map:* https://maps."&"app.goo.gl/DpPkfna7HQttxYXn9"" & CHAR(10) & CHAR(10) & ""📌 *தமிழ்*"" & CHAR(10) & ""வணக்கம் "" & B12 & "","" & CHAR(10) & ""உங்கள் கடிகார சர்வீஸ் முடிந்து, பெற்றுக்கொள்ள தயாராக உள்ளது."" & CHAR(10) & ""தயவுசெய்து கடைக்கு வந்து பெற்றுக்கொள்ளவும்."" & CHA"&"R(10) & ""பிராண்ட்: "" & D12 & CHAR(10) & ""பெறப்பட்ட தேதி: "" & TEXT(G12,""dd-mmm-yyyy"") & CHAR(10) & ""தயார் தேதி: "" & TEXT(H12,""dd-mmm-yyyy"") & CHAR(10) & ""மீதத் தொகை: ₹"" & K12 & CHAR(10) & CHAR(10) & ""🗺 *Google Map:* https://maps.app.goo.gl/D"&"pPkfna7HQttxYXn9"" & CHAR(10) & CHAR(10) & ""🙏 SMART TIMES SERVICE"" ), """") "),"") | R12: =HYPERLINK(Q12,"🟢 SEND WHATSAPP") -> 🟢 SEND WHATSAPP
P13: =IF(O13="YES", "https://wa.me/?text=" & ENCODEURL( IF(OR(L13="Pending",L13="In Progress"), "⚠ *SERVICE ALERT – ATTENTION REQUIRED*" & CHAR(10) & CHAR(10), "📢 *SERVICE STATUS UPDATE*" & CHAR(10) & CHAR(10) ) & "Service ID: " & A13 & CHAR(10) & "Customer: " & B13 & CHAR(10) & "Mobile: " & C13 & CHAR(10) & "Brand: " & D13 & CHAR(10) & "Problem: " & F13 & CHAR(10) & CHAR(10) & "Received Date: " & TEXT(G13,"dd-mmm-yyyy") & CHAR(10) & "Expected Delivery Date: " & TEXT(H13,"dd-mmm-yyyy") & CHAR(10) & "Current Status: *" & L13 & "*" & CHAR(10) & CHAR(10) & IF(OR(L13="Pending",L13="In Progress"), "⚠ Please follow up immediately.", "✅ Service update for information." ) & CHAR(10) & CHAR(10) & "Balance Amount: ₹" & K13 & CHAR(10) & CHAR(10) & "— SMART TIMES SERVICE" ), "") | Q13: =IFERROR(__xludf.DUMMYFUNCTION("IF(REGEXMATCH(LOWER(L13),""ready""), ""https://wa.me/91""&C13&""?text="" & ENCODEURL( ""📢 *SERVICE READY – READY FOR COLLECTION*"" & CHAR(10) & CHAR(10) & ""📌 *English*"" & CHAR(10) & ""Dear "" & B13 & "","" & CHAR(10) & ""Your watch service is comple"&"ted and ready for collection."" & CHAR(10) & ""Brand: "" & D13 & CHAR(10) & ""Problem: "" & F13 & CHAR(10) & ""Received Date: "" & TEXT(G13,""dd-mmm-yyyy"") & CHAR(10) & ""Ready Date: "" & TEXT(H13,""dd-mmm-yyyy"") & CHAR(10) & ""Balance Amount: ₹"" & K13"&" & CHAR(10) & CHAR(10) & ""📍 *Shop Address:*"" & CHAR(10) & ""SMART TIMES,"" & CHAR(10) & ""8/107, Pennagaram Main Road,"" & CHAR(10) & ""Next to R.C Church,"" & CHAR(10) & ""Dharmapuri – 636701"" & CHAR(10) & CHAR(10) & ""🗺 *Google Map:* https://maps."&"app.goo.gl/DpPkfna7HQttxYXn9"" & CHAR(10) & CHAR(10) & ""📌 *தமிழ்*"" & CHAR(10) & ""வணக்கம் "" & B13 & "","" & CHAR(10) & ""உங்கள் கடிகார சர்வீஸ் முடிந்து, பெற்றுக்கொள்ள தயாராக உள்ளது."" & CHAR(10) & ""தயவுசெய்து கடைக்கு வந்து பெற்றுக்கொள்ளவும்."" & CHA"&"R(10) & ""பிராண்ட்: "" & D13 & CHAR(10) & ""பெறப்பட்ட தேதி: "" & TEXT(G13,""dd-mmm-yyyy"") & CHAR(10) & ""தயார் தேதி: "" & TEXT(H13,""dd-mmm-yyyy"") & CHAR(10) & ""மீதத் தொகை: ₹"" & K13 & CHAR(10) & CHAR(10) & ""🗺 *Google Map:* https://maps.app.goo.gl/D"&"pPkfna7HQttxYXn9"" & CHAR(10) & CHAR(10) & ""🙏 SMART TIMES SERVICE"" ), """") "),"") | R13: =HYPERLINK(Q13,"🟢 SEND WHATSAPP") -> 🟢 SEND WHATSAPP
A14: 2492 | B14: MR.RAJA PANDI | C14: 8072204490 | D14: FASTRACK | E14: 3072SM(G) | F14: MG+SERVIVE | G14: 46026 | H14: 46036 | K14: =I14-J14 -> 0 | L14: Pending | O14: YES | P14: =IF(O14="YES", "https://wa.me/?text=" & ENCODEURL( IF(OR(L14="Pending",L14="In Progress"), "⚠ *SERVICE ALERT – ATTENTION REQUIRED*" & CHAR(10) & CHAR(10), "📢 *SERVICE STATUS UPDATE*" & CHAR(10) & CHAR(10) ) & "Service ID: " & A14 & CHAR(10) & "Customer: " & B14 & CHAR(10) & "Mobile: " & C14 & CHAR(10) & "Brand: " & D14 & CHAR(10) & "Problem: " & F14 & CHAR(10) & CHAR(10) & "Received Date: " & TEXT(G14,"dd-mmm-yyyy") & CHAR(10) & "Expected Delivery Date: " & TEXT(H14,"dd-mmm-yyyy") & CHAR(10) & "Current Status: *" & L14 & "*" & CHAR(10) & CHAR(10) & IF(OR(L14="Pending",L14="In Progress"), "⚠ Please follow up immediately.", "✅ Service update for information." ) & CHAR(10) & CHAR(10) & "Balance Amount: ₹" & K14 & CHAR(10) & CHAR(10) & "— SMART TIMES SERVICE" ), "") -> https://wa.me/?text=%F0%9F%93%A2%20%2ASERVICE%20STATUS%20UPDATE%2A%0A%0AService%20ID%3A%202492%0ACustomer%3A%20MR.RAJA%20PANDI%0AMobile%3A%208072204490%0ABrand%3A%20FASTRACK%0AProblem%3A%20MG%2BSERVIVE%0A%0AReceived%20Date%3A%2004-Jan-2026%0AExpected%20Delivery%20Date%3A%2014-Jan-2026%0ACurrent%20Status%3A%20%2APending%20%2A%0A%0A%E2%9C%85%20Service%20update%20for%20information.%0A%0ABalance%20Amount%3A%20%E2%82%B90%0A%0A%E2%80%94%20SMART%20TIMES%20SERVICE | Q14: =IFERROR(__xludf.DUMMYFUNCTION("IF(REGEXMATCH(LOWER(L14),""ready""), ""https://wa.me/91""&C14&""?text="" & ENCODEURL( ""📢 *SERVICE READY – READY FOR COLLECTION*"" & CHAR(10) & CHAR(10) & ""📌 *English*"" & CHAR(10) & ""Dear "" & B14 & "","" & CHAR(10) & ""Your watch service is comple"&"ted and ready for collection."" & CHAR(10) & ""Brand: "" & D14 & CHAR(10) & ""Problem: "" & F14 & CHAR(10) & ""Received Date: "" & TEXT(G14,""dd-mmm-yyyy"") & CHAR(10) & ""Ready Date: "" & TEXT(H14,""dd-mmm-yyyy"") & CHAR(10) & ""Balance Amount: ₹"" & K14"&" & CHAR(10) & CHAR(10) & ""📍 *Shop Address:*"" & CHAR(10) & ""SMART TIMES,"" & CHAR(10) & ""8/107, Pennagaram Main Road,"" & CHAR(10) & ""Next to R.C Church,"" & CHAR(10) & ""Dharmapuri – 636701"" & CHAR(10) & CHAR(10) & ""🗺 *Google Map:* https://maps."&"app.goo.gl/DpPkfna7HQttxYXn9"" & CHAR(10) & CHAR(10) & ""📌 *தமிழ்*"" & CHAR(10) & ""வணக்கம் "" & B14 & "","" & CHAR(10) & ""உங்கள் கடிகார சர்வீஸ் முடிந்து, பெற்றுக்கொள்ள தயாராக உள்ளது."" & CHAR(10) & ""தயவுசெய்து கடைக்கு வந்து பெற்றுக்கொள்ளவும்."" & CHA"&"R(10) & ""பிராண்ட்: "" & D14 & CHAR(10) & ""பெறப்பட்ட தேதி: "" & TEXT(G14,""dd-mmm-yyyy"") & CHAR(10) & ""தயார் தேதி: "" & TEXT(H14,""dd-mmm-yyyy"") & CHAR(10) & ""மீதத் தொகை: ₹"" & K14 & CHAR(10) & CHAR(10) & ""🗺 *Google Map:* https://maps.app.goo.gl/D"&"pPkfna7HQttxYXn9"" & CHAR(10) & CHAR(10) & ""🙏 SMART TIMES SERVICE"" ), """") "),"") | R14: =HYPERLINK(Q14,"🟢 SEND WHATSAPP") -> 🟢 SEND WHATSAPP | S14: =IF(S13<>"", "https://wa.me/?text=" & ENCODEURL( "⚠ *SERVICE PENDING SUMMARY*" & CHAR(10) & CHAR(10) & "Total Pending / In-Progress Watches: *" & COUNTIF(L:L,"Pending")+COUNTIF(L:L,"In Progress") & "*" & CHAR(10) & CHAR(10) & "📋 *Service IDs:*" & CHAR(10) & N13 & CHAR(10) & CHAR(10) & "Please follow up today." & CHAR(10) & CHAR(10) & "— SMART TIMES SERVICE" ), "")
A15: 2492 | B15: MR.RAJA PANDI | C15: 8072204490 | D15: TITAN | E15: 1650YM(G) | F15: CUP+SERVIVE | G15: 46026 | H15: 46036 | L15: Pending | O15: YES | P15: =IF(O15="YES", "https://wa.me/?text=" & ENCODEURL( IF(OR(L15="Pending",L15="In Progress"), "⚠ *SERVICE ALERT – ATTENTION REQUIRED*" & CHAR(10) & CHAR(10), "📢 *SERVICE STATUS UPDATE*" & CHAR(10) & CHAR(10) ) & "Service ID: " & A15 & CHAR(10) & "Customer: " & B15 & CHAR(10) & "Mobile: " & C15 & CHAR(10) & "Brand: " & D15 & CHAR(10) & "Problem: " & F15 & CHAR(10) & CHAR(10) & "Received Date: " & TEXT(G15,"dd-mmm-yyyy") & CHAR(10) & "Expected Delivery Date: " & TEXT(H15,"dd-mmm-yyyy") & CHAR(10) & "Current Status: *" & L15 & "*" & CHAR(10) & CHAR(10) & IF(OR(L15="Pending",L15="In Progress"), "⚠ Please follow up immediately.", "✅ Service update for information." ) & CHAR(10) & CHAR(10) & "Balance Amount: ₹" & K15 & CHAR(10) & CHAR(10) & "— SMART TIMES SERVICE" ), "") -> https://wa.me/?text=%F0%9F%93%A2%20%2ASERVICE%20STATUS%20UPDATE%2A%0A%0AService%20ID%3A%202492%0ACustomer%3A%20MR.RAJA%20PANDI%0AMobile%3A%208072204490%0ABrand%3A%20TITAN%0AProblem%3A%20CUP%2BSERVIVE%0A%0AReceived%20Date%3A%2004-Jan-2026%0AExpected%20Delivery%20Date%3A%2014-Jan-2026%0ACurrent%20Status%3A%20%2APending%20%2A%0A%0A%E2%9C%85%20Service%20update%20for%20information.%0A%0ABalance%20Amount%3A%20%E2%82%B9%0A%0A%E2%80%94%20SMART%20TIMES%20SERVICE | Q15: =IFERROR(__xludf.DUMMYFUNCTION("IF(REGEXMATCH(LOWER(L15),""ready""), ""https://wa.me/91""&C15&""?text="" & ENCODEURL( ""📢 *SERVICE READY – READY FOR COLLECTION*"" & CHAR(10) & CHAR(10) & ""📌 *English*"" & CHAR(10) & ""Dear "" & B15 & "","" & CHAR(10) & ""Your watch service is comple"&"ted and ready for collection."" & CHAR(10) & ""Brand: "" & D15 & CHAR(10) & ""Problem: "" & F15 & CHAR(10) & ""Received Date: "" & TEXT(G15,""dd-mmm-yyyy"") & CHAR(10) & ""Ready Date: "" & TEXT(H15,""dd-mmm-yyyy"") & CHAR(10) & ""Balance Amount: ₹"" & K15"&" & CHAR(10) & CHAR(10) & ""📍 *Shop Address:*"" & CHAR(10) & ""SMART TIMES,"" & CHAR(10) & ""8/107, Pennagaram Main Road,"" & CHAR(10) & ""Next to R.C Church,"" & CHAR(10) & ""Dharmapuri – 636701"" & CHAR(10) & CHAR(10) & ""🗺 *Google Map:* https://maps."&"app.goo.gl/DpPkfna7HQttxYXn9"" & CHAR(10) & CHAR(10) & ""📌 *தமிழ்*"" & CHAR(10) & ""வணக்கம் "" & B15 & "","" & CHAR(10) & ""உங்கள் கடிகார சர்வீஸ் முடிந்து, பெற்றுக்கொள்ள தயாராக உள்ளது."" & CHAR(10) & ""தயவுசெய்து கடைக்கு வந்து பெற்றுக்கொள்ளவும்."" & CHA"&"R(10) & ""பிராண்ட்: "" & D15 & CHAR(10) & ""பெறப்பட்ட தேதி: "" & TEXT(G15,""dd-mmm-yyyy"") & CHAR(10) & ""தயார் தேதி: "" & TEXT(H15,""dd-mmm-yyyy"") & CHAR(10) & ""மீதத் தொகை: ₹"" & K15 & CHAR(10) & CHAR(10) & ""🗺 *Google Map:* https://maps.app.goo.gl/D"&"pPkfna7HQttxYXn9"" & CHAR(10) & CHAR(10) & ""🙏 SMART TIMES SERVICE"" ), """") "),"") | R15: =HYPERLINK(Q15,"🟢 SEND WHATSAPP") -> 🟢 SEND WHATSAPP | S15: =IF(S14<>"", "https://wa.me/?text=" & ENCODEURL( "⚠ *SERVICE PENDING SUMMARY*" & CHAR(10) & CHAR(10) & "Total Pending / In-Progress Watches: *" & COUNTIF(L:L,"Pending")+COUNTIF(L:L,"In Progress") & "*" & CHAR(10) & CHAR(10) & "📋 *Service IDs:*" & CHAR(10) & N14 & CHAR(10) & CHAR(10) & "Please follow up today." & CHAR(10) & CHAR(10) & "— SMART TIMES SERVICE" ), "")
A16: =A14+1 -> 2493 | B16: MR.MANI VEL | C16: 8344805985 | D16: TITAN | E16: 161YM(G) | F16: CASE+CHAIN+BATTERY(721) | G16: 46026 | H16: 46026 | I16: 1500 | K16: =I16-J16 -> 1500 | L16: Ready | O16: YES | P16: =IF(O16="YES", "https://wa.me/?text=" & ENCODEURL( IF(OR(L16="Pending",L16="In Progress"), "⚠ *SERVICE ALERT – ATTENTION REQUIRED*" & CHAR(10) & CHAR(10), "📢 *SERVICE STATUS UPDATE*" & CHAR(10) & CHAR(10) ) & "Service ID: " & A16 & CHAR(10) & "Customer: " & B16 & CHAR(10) & "Mobile: " & C16 & CHAR(10) & "Brand: " & D16 & CHAR(10) & "Problem: " & F16 & CHAR(10) & CHAR(10) & "Received Date: " & TEXT(G16,"dd-mmm-yyyy") & CHAR(10) & "Expected Delivery Date: " & TEXT(H16,"dd-mmm-yyyy") & CHAR(10) & "Current Status: *" & L16 & "*" & CHAR(10) & CHAR(10) & IF(OR(L16="Pending",L16="In Progress"), "⚠ Please follow up immediately.", "✅ Service update for information." ) & CHAR(10) & CHAR(10) & "Balance Amount: ₹" & K16 & CHAR(10) & CHAR(10) & "— SMART TIMES SERVICE" ), "") -> https://wa.me/?text=%F0%9F%93%A2%20%2ASERVICE%20STATUS%20UPDATE%2A%0A%0AService%20ID%3A%202493%0ACustomer%3A%20MR.MANI%20VEL%0AMobile%3A%208344805985%0ABrand%3A%20TITAN%0AProblem%3A%20CASE%2BCHAIN%2BBATTERY%28721%29%0A%0AReceived%20Date%3A%2004-Jan-2026%0AExpected%20Delivery%20Date%3A%2004-Jan-2026%0ACurrent%20Status%3A%20%2AReady%2A%0A%0A%E2%9C%85%20Service%20update%20for%20information.%0A%0ABalance%20Amount%3A%20%E2%82%B91500%0A%0A%E2%80%94%20SMART%20TIMES%20SERVICE | Q16: =IFERROR(__xludf.DUMMYFUNCTION("IF(REGEXMATCH(LOWER(L16),""ready""), ""https://wa.me/91""&C16&""?text="" & ENCODEURL( ""📢 *SERVICE READY – READY FOR COLLECTION*"" & CHAR(10) & CHAR(10) & ""📌 *English*"" & CHAR(10) & ""Dear "" & B16 & "","" & CHAR(10) & ""Your watch service is comple"&"ted and ready for collection."" & CHAR(10) & ""Brand: "" & D16 & CHAR(10) & ""Problem: "" & F16 & CHAR(10) & ""Received Date: "" & TEXT(G16,""dd-mmm-yyyy"") & CHAR(10) & ""Ready Date: "" & TEXT(H16,""dd-mmm-yyyy"") & CHAR(10) & ""Balance Amount: ₹"" & K16"&" & CHAR(10) & CHAR(10) & ""📍 *Shop Address:*"" & CHAR(10) & ""SMART TIMES,"" & CHAR(10) & ""8/107, Pennagaram Main Road,"" & CHAR(10) & ""Next to R.C Church,"" & CHAR(10) & ""Dharmapuri – 636701"" & CHAR(10) & CHAR(10) & ""🗺 *Google Map:* https://maps."&"app.goo.gl/DpPkfna7HQttxYXn9"" & CHAR(10) & CHAR(10) & ""📌 *தமிழ்*"" & CHAR(10) & ""வணக்கம் "" & B16 & "","" & CHAR(10) & ""உங்கள் கடிகார சர்வீஸ் முடிந்து, பெற்றுக்கொள்ள தயாராக உள்ளது."" & CHAR(10) & ""தயவுசெய்து கடைக்கு வந்து பெற்றுக்கொள்ளவும்."" & CHA"&"R(10) & ""பிராண்ட்: "" & D16 & CHAR(10) & ""பெறப்பட்ட தேதி: "" & TEXT(G16,""dd-mmm-yyyy"") & CHAR(10) & ""தயார் தேதி: "" & TEXT(H16,""dd-mmm-yyyy"") & CHAR(10) & ""மீதத் தொகை: ₹"" & K16 & CHAR(10) & CHAR(10) & ""🗺 *Google Map:* https://maps.app.goo.gl/D"&"pPkfna7HQttxYXn9"" & CHAR(10) & CHAR(10) & ""🙏 SMART TIMES SERVICE"" ), """") "),"https://wa.me/918344805985?text=%F0%9F%93%A2%20%2ASERVICE%20READY%20%E2%80%93%20READY%20FOR%20COLLECTION%2A%0A%0A%F0%9F%93%8C%20%2AEnglish%2A%0ADear%20MR.MANI%20VEL%2C%0AYour%20watch%20service%20is%20completed%20and%20ready%20for%20collection.%0ABrand%3A%"&"20TITAN%0AProblem%3A%20CASE%2BCHAIN%2BBATTERY%28721%29%0AReceived%20Date%3A%2004-Jan-2026%0AReady%20Date%3A%2004-Jan-2026%0ABalance%20Amount%3A%20%E2%82%B91500%0A%0A%F0%9F%93%8D%20%2AShop%20Address%3A%2A%0ASMART%20TIMES%2C%0A8%2F107%2C%20Pennagaram%20Main"&"%20Road%2C%0ANext%20to%20R.C%20Church%2C%0ADharmapuri%20%E2%80%93%20636701%0A%0A%F0%9F%97%BA%20%2AGoogle%20Map%3A%2A%20https%3A%2F%2Fmaps.app.goo.gl%2FDpPkfna7HQttxYXn9%0A%0A%F0%9F%93%8C%20%2A%E0%AE%A4%E0%AE%AE%E0%AE%BF%E0%AE%B4%E0%AF%8D%2A%0A%E0%AE%B5%E0"&"%AE%A3%E0%AE%95%E0%AF%8D%E0%AE%95%E0%AE%AE%E0%AF%8D%20MR.MANI%20VEL%2C%0A%E0%AE%89%E0%AE%99%E0%AF%8D%E0%AE%95%E0%AE%B3%E0%AF%8D%20%E0%AE%95%E0%AE%9F%E0%AE%BF%E0%AE%95%E0%AE%BE%E0%AE%B0%20%E0%AE%9A%E0%AE%B0%E0%AF%8D%E0%AE%B5%E0%AF%80%E0%AE%B8%E0%AF%8D%20%E"&"0%AE%AE%E0%AF%81%E0%AE%9F%E0%AE%BF%E0%AE%A8%E0%AF%8D%E0%AE%A4%E0%AF%81%2C%20%E0%AE%AA%E0%AF%86%E0%AE%B1%E0%AF%8D%E0%AE%B1%E0%AF%81%E0%AE%95%E0%AF%8D%E0%AE%95%E0%AF%8A%E0%AE%B3%E0%AF%8D%E0%AE%B3%20%E0%AE%A4%E0%AE%AF%E0%AE%BE%E0%AE%B0%E0%AE%BE%E0%AE%95%20%E"&"0%AE%89%E0%AE%B3%E0%AF%8D%E0%AE%B3%E0%AE%A4%E0%AF%81.%0A%E0%AE%A4%E0%AE%AF%E0%AE%B5%E0%AF%81%E0%AE%9A%E0%AF%86%E0%AE%AF%E0%AF%8D%E0%AE%A4%E0%AF%81%20%E0%AE%95%E0%AE%9F%E0%AF%88%E0%AE%95%E0%AF%8D%E0%AE%95%E0%AF%81%20%E0%AE%B5%E0%AE%A8%E0%AF%8D%E0%AE%A4%E0%"&"AF%81%20%E0%AE%AA%E0%AF%86%E0%AE%B1%E0%AF%8D%E0%AE%B1%E0%AF%81%E0%AE%95%E0%AF%8D%E0%AE%95%E0%AF%8A%E0%AE%B3%E0%AF%8D%E0%AE%B3%E0%AE%B5%E0%AF%81%E0%AE%AE%E0%AF%8D.%0A%E0%AE%AA%E0%AE%BF%E0%AE%B0%E0%AE%BE%E0%AE%A3%E0%AF%8D%E0%AE%9F%E0%AF%8D%3A%20TITAN%0A%E0%"&"AE%AA%E0%AF%86%E0%AE%B1%E0%AE%AA%E0%AF%8D%E0%AE%AA%E0%AE%9F%E0%AF%8D%E0%AE%9F%20%E0%AE%A4%E0%AF%87%E0%AE%A4%E0%AE%BF%3A%2004-Jan-2026%0A%E0%AE%A4%E0%AE%AF%E0%AE%BE%E0%AE%B0%E0%AF%8D%20%E0%AE%A4%E0%AF%87%E0%AE%A4%E0%AE%BF%3A%2004-Jan-2026%0A%E0%AE%AE%E0%AF"&"%80%E0%AE%A4%E0%AE%A4%E0%AF%8D%20%E0%AE%A4%E0%AF%8A%E0%AE%95%E0%AF%88%3A%20%E2%82%B91500%0A%0A%F0%9F%97%BA%20%2AGoogle%20Map%3A%2A%20https%3A%2F%2Fmaps.app.goo.gl%2FDpPkfna7HQttxYXn9%0A%0A%F0%9F%99%8F%20SMART%20TIMES%20SERVICE") -> https://wa.me/918344805985?text=%F0%9F%93%A2%20%2ASERVICE%20READY%20%E2%80%93%20READY%20FOR%20COLLECTION%2A%0A%0A%F0%9F%93%8C%20%2AEnglish%2A%0ADear%20MR.MANI%20VEL%2C%0AYour%20watch%20service%20is%20completed%20and%20ready%20for%20collection.%0ABrand%3A%20TITAN%0AProblem%3A%20CASE%2BCHAIN%2BBATTERY%28721%29%0AReceived%20Date%3A%2004-Jan-2026%0AReady%20Date%3A%2004-Jan-2026%0ABalance%20Amount%3A%20%E2%82%B91500%0A%0A%F0%9F%93%8D%20%2AShop%20Address%3A%2A%0ASMART%20TIMES%2C%0A8%2F107%2C%20Pennagaram%20Main%20Road%2C%0ANext%20to%20R.C%20Church%2C%0ADharmapuri%20%E2%80%93%20636701%0A%0A%F0%9F%97%BA%20%2AGoogle%20Map%3A%2A%20https%3A%2F%2Fmaps.app.goo.gl%2FDpPkfna7HQttxYXn9%0A%0A%F0%9F%93%8C%20%2A%E0%AE%A4%E0%AE%AE%E0%AE%BF%E0%AE%B4%E0%AF%8D%2A%0A%E0%AE%B5%E0%AE%A3%E0%AE%95%E0%AF%8D%E0%AE%95%E0%AE%AE%E0%AF%8D%20MR.MANI%20VEL%2C%0A%E0%AE%89%E0%AE%99%E0%AF%8D%E0%AE%95%E0%AE%B3%E0%AF%8D%20%E0%AE%95%E0%AE%9F%E0%AE%BF%E0%AE%95%E0%AE%BE%E0%AE%B0%20%E0%AE%9A%E0%AE%B0%E0%AF%8D%E0%AE%B5%E0%AF%80%E0%AE%B8%E0%AF%8D%20%E0%AE%AE%E0%AF%81%E0%AE%9F%E0%AE%BF%E0%AE%A8%E0%AF%8D%E0%AE%A4%E0%AF%81%2C%20%E0%AE%AA%E0%AF%86%E0%AE%B1%E0%AF%8D%E0%AE%B1%E0%AF%81%E0%AE%95%E0%AF%8D%E0%AE%95%E0%AF%8A%E0%AE%B3%E0%AF%8D%E0%AE%B3%20%E0%AE%A4%E0%AE%AF%E0%AE%BE%E0%AE%B0%E0%AE%BE%E0%AE%95%20%E0%AE%89%E0%AE%B3%E0%AF%8D%E0%AE%B3%E0%AE%A4%E0%AF%81.%0A%E0%AE%A4%E0%AE%AF%E0%AE%B5%E0%AF%81%E0%AE%9A%E0%AF%86%E0%AE%AF%E0%AF%8D%E0%AE%A4%E0%AF%81%20%E0%AE%95%E0%AE%9F%E0%AF%88%E0%AE%95%E0%AF%8D%E0%AE%95%E0%AF%81%20%E0%AE%B5%E0%AE%A8%E0%AF%8D%E0%AE%A4%E0%AF%81%20%E0%AE%AA%E0%AF%86%E0%AE%B1%E0%AF%8D%E0%AE%B1%E0%AF%81%E0%AE%95%E0%AF%8D%E0%AE%95%E0%AF%8A%E0%AE%B3%E0%AF%8D%E0%AE%B3%E0%AE%B5%E0%AF%81%E0%AE%AE%E0%AF%8D.%0A%E0%AE%AA%E0%AE%BF%E0%AE%B0%E0%AE%BE%E0%AE%A3%E0%AF%8D%E0%AE%9F%E0%AF%8D%3A%20TITAN%0A%E0%AE%AA%E0%AF%86%E0%AE%B1%E0%AE%AA%E0%AF%8D%E0%AE%AA%E0%AE%9F%E0%AF%8D%E0%AE%9F%20%E0%AE%A4%E0%AF%87%E0%AE%A4%E0%AE%BF%3A%2004-Jan-2026%0A%E0%AE%A4%E0%AE%AF%E0%AE%BE%E0%AE%B0%E0%AF%8D%20%E0%AE%A4%E0%AF%87%E0%AE%A4%E0%AE%BF%3A%2004-Jan-2026%0A%E0%AE%AE%E0%AF%80%E0%AE%A4%E0%AE%A4%E0%AF%8D%20%E0%AE%A4%E0%AF%8A%E0%AE%95%E0%AF%88%3A%20%E2%82%B91500%0A%0A%F0%9F%97%BA%20%2AGoogle%20Map%3A%2A%20https%3A%2F%2Fmaps.app.goo.gl%2FDpPkfna7HQttxYXn9%0A%0A%F0%9F%99%8F%20SMART%20TIMES%20SERVICE | R16: =HYPERLINK(Q16,"🟢 SEND WHATSAPP") -> 🟢 SEND WHATSAPP
